Workbook

Sheet Directorio
A1: Directorio de gestores y analistas — Janus Henderson | H1: Resultados: | I1: =IFERROR(ROWS(_xlfn.ANCHORARRAY(A9)),0) -> 130
A2: Búsqueda rápida para peticiones de prensa. Filtra arriba o usa los menús de la tabla.
A4: Nombre contiene | B4: Clase de activo | C4: Sub-clase / estilo | D4: Región | E4: Temática contiene | F4: Tipo de rol
A6: (deja en blanco para 'cualquiera') | E6: (deja en blanco para 'cualquiera')
A8: Nombre | B8: Rol oficial | C8: Clase de activo | D8: Sub-clase | E8: Región | F8: Temática | G8: Fondo | H8: Bio | I8: Fondo (URL)
A9: {=IFERROR(_xlfn.CHOOSECOLS(_xlfn._xlws.FILTER(JHers!A3:K132,(((A5="")+ISNUMBER(SEARCH(A5,JHers!A3:A132)))>0)*(((B5="")+(JHers!D3:D132=B5))>0)*(((C5="")+(JHers!E3:E132=C5))>0)*(((D5="")+(JHers!F3:F132=D5))>0)*(((E5="")+ISNUMBER(SEARCH(E5,JHers!G3:G132)))>0)*(((F5="")+(JHers!C3:C132=F5))>0),"Sin resultados"),1,2,4,5,6,7,8,10,11),"Sin resultados")} -> Allan Maymin | B9: Co-Head of Global Asset Allocation | Portfolio Manager | C9: Multiactivo | D9: Global adaptive multi-asset allocation | E9: Global | F9: Asignación de activos / multiactivo cuantitativo | G9: Global Adaptive Multi-Asset Fund | H9: https://www.janushenderson.com/corporate/bio/allan-maymin/ | I9: https://www.janushenderson.com/es-es/advisor/product/janus-henderson-global-adaptive-multi-asset-fund/
A10: Daniel Sullivan | B10: Portfolio Manager (Head of Global Natural Resources) | C10: Renta variable | D10: Global natural resources equities | E10: Global | F10: Recursos naturales / energía / transición energética | G10: Global Natural Resources Fund | H10: https://www.janushenderson.com/corporate/bio/daniel-sullivan/ | I10: https://www.janushenderson.com/en-au/adviser/product/janus-henderson-global-natural-resources-fund/
A11: Darko Kuzmanovic | B11: Portfolio Manager (Global Natural Resources Team) | C11: Renta variable | D11: Global natural resources equities | E11: Global | F11: Recursos naturales / minería / energía | G11: Global Natural Resources Fund | H11: https://www.janushenderson.com/en-au/investor/bio/darko-kuzmanovic/ | I11: https://www.janushenderson.com/en-au/adviser/product/janus-henderson-global-natural-resources-fund/
A12: Dillan Shah, CFA | B12: Quantitative Research Analyst | C12: Renta fija | D12: Renta fija global cuantitativa | E12: Global | F12: Bonos globales / renta fija cuantitativa | G12: NO_DATO | H12: https://www.janushenderson.com/en-us/advisor/bio/dillan-shah/ | I12: NO_DATO
A13: James Briggs, CFA | B13: Portfolio Manager (Corporate Credit Team) | C13: Renta fija | D13: Crédito corporativo investment grade / Buy & Maintain | E13: Global | F13: Crédito corporativo IG / carteras buy & maintain / ESG en renta fija | G13: Global Investment Grade & Buy and Maintain Credit Strategies | H13: https://www.janushenderson.com/en-gb/investor/bio/james-briggs-aca-cfa/ | I13: NO_DATO
A14: Mark Richardson | B14: Portfolio Manager (Diversified Alternatives Team) | C14: Alternativos | D14: Diversified alternatives / estrategias cuantitativas | E14: Global | F14: Alternativos líquidos / estrategias sistemáticas | G14: Diversified Alternatives quantitative strategies | H14: https://www.janushenderson.com/en-be/advisor/bio/mark-richardson-dphil/ | I14: NO_DATO
A15: Nick Schommer, CFA | B15: Portfolio Manager | C15: Renta variable | D15: US large/mid-cap growth | E15: Estados Unidos | F15: Renta variable estadounidense growth | G15: US Growth / related US equity growth strategies | H15: https://www.janushenderson.com/en-us/advisor/bio/nick-schommer-cfa/ | I15: NO_DATO
A16: Nick Schommer, CFA | B16: Portfolio Manager | C16: Renta variable | D16: US mid-cap blend / contrarian | E16: Estados Unidos | F16: Renta variable estadounidense / enfoque contrarian | G16: Janus Henderson Contrarian Fund | H16: https://www.janushenderson.com/en-us/advisor/bio/nick-schommer-cfa/ | I16: NO_DATO
A17: Oliver Blackbourn, CFA | B17: Portfolio Manager (Multi-Asset Team) | C17: Multiactivo | D17: Flexible multi-asset portfolios | E17: Global | F17: Multiactivo global / visión macro | G17: Multi-Asset flexible strategies | H17: https://www.janushenderson.com/en-gb/investor/bio/oliver-blackbourn-cfa/ | I17: NO_DATO
A18: Ali Dibadj | B18: Chief Executive Officer | C18: Perfil ejecutivo | D18: Dirección corporativa / estrategia | E18: Global | F18: Gestión de activos / estrategia corporativa / ESG corporativo | G18: NO_DATO | H18: https://www.janushenderson.com/en-fi/advisor/bio/ali-dibadj/ | I18: NO_DATO
A19: Aaron Schaechterle | B19: Portfolio Manager | Research Analyst | C19: Renta variable | D19: US small/mid-cap growth | E19: Estados Unidos | F19: Small & mid cap growth / tecnología / industriales | G19: US Venture Fund | H19: https://www.janushenderson.com/corporate/bio/aaron-schaechterle/ | I19: NO_DATO
A20: Aaron Schaechterle | B20: Portfolio Manager | Research Analyst | C20: Renta variable | D20: US SMID Cap Growth | E20: Estados Unidos | F20: Small & mid cap growth / modelos de negocio diferenciados | G20: US SMID Cap Growth Managed Account | H20: https://www.janushenderson.com/corporate/bio/aaron-schaechterle/ | I20: https://www.janushenderson.com/en-us/advisor/product/us-smid-cap-growth-managed-account/
A21: Aaron Scully, CFA | B21: Portfolio Manager | C21: Renta variable | D21: Global sustainable equity | E21: Global | F21: ESG / sostenibilidad | G21: Horizon Global Sustainable Equity Fund | H21: https://www.janushenderson.com/en-us/advisor/bio/aaron-scully-cfa/ | I21: NO_DATO
... A138: William Cassidy | B138: Chief Technology Officer | C138: Perfil ejecutivo | D138: Tecnología e infraestructura corporativa | E138: Global | F138: Estrategia tecnológica / innovación / datos | G138: NO_DATO | H138: https://www.janushenderson.com/en/row/bio/william-cassidy/ | I138: NO_DATO
A146: Directorio completo (usa los menús de columna para filtrar)
A148: Nombre | B148: Rol oficial | C148: Tipo rol | D148: Clase de activo | E148: Sub-clase / estilo | F148: Región | G148: Temática | H148: Fondo | I148: ISIN / ticker | J148: URL bio | K148: URL fondo
A149: =IFERROR(IF(JHers!A3="","",JHers!A3),"") -> Allan Maymin | B149: =IFERROR(IF(JHers!B3="","",JHers!B3),"") -> Co-Head of Global Asset Allocation | Portfolio Manager | C149: =IFERROR(IF(JHers!C3="","",JHers!C3),"") -> Portfolio Manager | D149: =IFERROR(IF(JHers!D3="","",JHers!D3),"") -> Multiactivo | E149: =IFERROR(IF(JHers!E3="","",JHers!E3),"") -> Global adaptive multi-asset allocation | F149: =IFERROR(IF(JHers!F3="","",JHers!F3),"") -> Global | G149: =IFERROR(IF(JHers!G3="","",JHers!G3),"") -> Asignación de activos / multiactivo cuantitativo | H149: =IFERROR(IF(JHers!H3="","",JHers!H3),"") -> Global Adaptive Multi-Asset Fund | ... K149: =IFERROR(IF(JHers!K3="","",JHers!K3),"") -> https://www.janushenderson.com/es-es/advisor/product/janus-henderson-global-adaptive-multi-asset-fund/
A150: =IFERROR(IF(JHers!A4="","",JHers!A4),"") -> Daniel Sullivan | B150: =IFERROR(IF(JHers!B4="","",JHers!B4),"") -> Portfolio Manager (Head of Global Natural Resources) | C150: =IFERROR(IF(JHers!C4="","",JHers!C4),"") -> Portfolio Manager | D150: =IFERROR(IF(JHers!D4="","",JHers!D4),"") -> Renta variable | E150: =IFERROR(IF(JHers!E4="","",JHers!E4),"") -> Global natural resources equities | F150: =IFERROR(IF(JHers!F4="","",JHers!F4),"") -> Global | G150: =IFERROR(IF(JHers!G4="","",JHers!G4),"") -> Recursos naturales / energía / transición energética | H150: =IFERROR(IF(JHers!H4="","",JHers!H4),"") -> Global Natural Resources Fund | ... K150: =IFERROR(IF(JHers!K4="","",JHers!K4),"") -> https://www.janushenderson.com/en-au/adviser/product/janus-henderson-global-natural-resources-fund/
A151: =IFERROR(IF(JHers!A5="","",JHers!A5),"") -> Darko Kuzmanovic | B151: =IFERROR(IF(JHers!B5="","",JHers!B5),"") -> Portfolio Manager (Global Natural Resources Team) | C151: =IFERROR(IF(JHers!C5="","",JHers!C5),"") -> Portfolio Manager | D151: =IFERROR(IF(JHers!D5="","",JHers!D5),"") -> Renta variable | E151: =IFERROR(IF(JHers!E5="","",JHers!E5),"") -> Global natural resources equities | F151: =IFERROR(IF(JHers!F5="","",JHers!F5),"") -> Global | G151: =IFERROR(IF(JHers!G5="","",JHers!G5),"") -> Recursos naturales / minería / energía | H151: =IFERROR(IF(JHers!H5="","",JHers!H5),"") -> Global Natural Resources Fund | ... K151: =IFERROR(IF(JHers!K5="","",JHers!K5),"") -> https://www.janushenderson.com/en-au/adviser/product/janus-henderson-global-natural-resources-fund/
A152: =IFERROR(IF(JHers!A6="","",JHers!A6),"") -> Dillan Shah, CFA | B152: =IFERROR(IF(JHers!B6="","",JHers!B6),"") -> Quantitative Research Analyst | C152: =IFERROR(IF(JHers!C6="","",JHers!C6),"") -> Analista | D152: =IFERROR(IF(JHers!D6="","",JHers!D6),"") -> Renta fija | E152: =IFERROR(IF(JHers!E6="","",JHers!E6),"") -> Renta fija global cuantitativa | F152: =IFERROR(IF(JHers!F6="","",JHers!F6),"") -> Global | G152: =IFERROR(IF(JHers!G6="","",JHers!G6),"") -> Bonos globales / renta fija cuantitativa | H152: =IFERROR(IF(JHers!H6="","",JHers!H6),"") -> NO_DATO | ... K152: =IFERROR(IF(JHers!K6="","",JHers!K6),"") -> NO_DATO
A153: =IFERROR(IF(JHers!A7="","",JHers!A7),"") -> James Briggs, CFA | B153: =IFERROR(IF(JHers!B7="","",JHers!B7),"") -> Portfolio Manager (Corporate Credit Team) | C153: =IFERROR(IF(JHers!C7="","",JHers!C7),"") -> Portfolio Manager | D153: =IFERROR(IF(JHers!D7="","",JHers!D7),"") -> Renta fija | E153: =IFERROR(IF(JHers!E7="","",JHers!E7),"") -> Crédito corporativo investment grade / Buy & Maintain | F153: =IFERROR(IF(JHers!F7="","",JHers!F7),"") -> Global | G153: =IFERROR(IF(JHers!G7="","",JHers!G7),"") -> Crédito corporativo IG / carteras buy & maintain / ESG en renta fija | H153: =IFERROR(IF(JHers!H7="","",JHers!H7),"") -> Global Investment Grade & Buy and Maintain Credit Strategies | ... K153: =IFERROR(IF(JHers!K7="","",JHers!K7),"") -> NO_DATO
A154: =IFERROR(IF(JHers!A8="","",JHers!A8),"") -> Mark Richardson | B154: =IFERROR(IF(JHers!B8="","",JHers!B8),"") -> Portfolio Manager (Diversified Alternatives Team) | C154: =IFERROR(IF(JHers!C8="","",JHers!C8),"") -> Portfolio Manager | D154: =IFERROR(IF(JHers!D8="","",JHers!D8),"") -> Alternativos | E154: =IFERROR(IF(JHers!E8="","",JHers!E8),"") -> Diversified alternatives / estrategias cuantitativas | F154: =IFERROR(IF(JHers!F8="","",JHers!F8),"") -> Global | G154: =IFERROR(IF(JHers!G8="","",JHers!G8),"") -> Alternativos líquidos / estrategias sistemáticas | H154: =IFERROR(IF(JHers!H8="","",JHers!H8),"") -> Diversified Alternatives quantitative strategies | ... K154: =IFERROR(IF(JHers!K8="","",JHers!K8),"") -> NO_DATO
A155: =IFERROR(IF(JHers!A9="","",JHers!A9),"") -> Nick Schommer, CFA | B155: =IFERROR(IF(JHers!B9="","",JHers!B9),"") -> Portfolio Manager | C155: =IFERROR(IF(JHers!C9="","",JHers!C9),"") -> Portfolio Manager | D155: =IFERROR(IF(JHers!D9="","",JHers!D9),"") -> Renta variable | E155: =IFERROR(IF(JHers!E9="","",JHers!E9),"") -> US large/mid-cap growth | F155: =IFERROR(IF(JHers!F9="","",JHers!F9),"") -> Estados Unidos | G155: =IFERROR(IF(JHers!G9="","",JHers!G9),"") -> Renta variable estadounidense growth | H155: =IFERROR(IF(JHers!H9="","",JHers!H9),"") -> US Growth / related US equity growth strategies | ... K155: =IFERROR(IF(JHers!K9="","",JHers!K9),"") -> NO_DATO
A156: =IFERROR(IF(JHers!A10="","",JHers!A10),"") -> Nick Schommer, CFA | B156: =IFERROR(IF(JHers!B10="","",JHers!B10),"") -> Portfolio Manager | C156: =IFERROR(IF(JHers!C10="","",JHers!C10),"") -> Portfolio Manager | D156: =IFERROR(IF(JHers!D10="","",JHers!D10),"") -> Renta variable | E156: =IFERROR(IF(JHers!E10="","",JHers!E10),"") -> US mid-cap blend / contrarian | F156: =IFERROR(IF(JHers!F10="","",JHers!F10),"") -> Estados Unidos | G156: =IFERROR(IF(JHers!G10="","",JHers!G10),"") -> Renta variable estadounidense / enfoque contrarian | H156: =IFERROR(IF(JHers!H10="","",JHers!H10),"") -> Janus Henderson Contrarian Fund | ... K156: =IFERROR(IF(JHers!K10="","",JHers!K10),"") -> NO_DATO
A157: =IFERROR(IF(JHers!A11="","",JHers!A11),"") -> Oliver Blackbourn, CFA | B157: =IFERROR(IF(JHers!B11="","",JHers!B11),"") -> Portfolio Manager (Multi-Asset Team) | C157: =IFERROR(IF(JHers!C11="","",JHers!C11),"") -> Portfolio Manager | D157: =IFERROR(IF(JHers!D11="","",JHers!D11),"") -> Multiactivo | E157: =IFERROR(IF(JHers!E11="","",JHers!E11),"") -> Flexible multi-asset portfolios | F157: =IFERROR(IF(JHers!F11="","",JHers!F11),"") -> Global | G157: =IFERROR(IF(JHers!G11="","",JHers!G11),"") -> Multiactivo global / visión macro | H157: =IFERROR(IF(JHers!H11="","",JHers!H11),"") -> Multi-Asset flexible strategies | ... K157: =IFERROR(IF(JHers!K11="","",JHers!K11),"") -> NO_DATO
A158: =IFERROR(IF(JHers!A12="","",JHers!A12),"") -> Ali Dibadj | B158: =IFERROR(IF(JHers!B12="","",JHers!B12),"") -> Chief Executive Officer | C158: =IFERROR(IF(JHers!C12="","",JHers!C12),"") -> Otro | D158: =IFERROR(IF(JHers!D12="","",JHers!D12),"") -> Perfil ejecutivo | E158: =IFERROR(IF(JHers!E12="","",JHers!E12),"") -> Dirección corporativa / estrategia | F158: =IFERROR(IF(JHers!F12="","",JHers!F12),"") -> Global | G158: =IFERROR(IF(JHers!G12="","",JHers!G12),"") -> Gestión de activos / estrategia corporativa / ESG corporativo | H158: =IFERROR(IF(JHers!H12="","",JHers!H12),"") -> NO_DATO | ... K158: =IFERROR(IF(JHers!K12="","",JHers!K12),"") -> NO_DATO
A159: =IFERROR(IF(JHers!A13="","",JHers!A13),"") -> Aaron Schaechterle | B159: =IFERROR(IF(JHers!B13="","",JHers!B13),"") -> Portfolio Manager | Research Analyst | C159: =IFERROR(IF(JHers!C13="","",JHers!C13),"") -> Portfolio Manager + Analista | D159: =IFERROR(IF(JHers!D13="","",JHers!D13),"") -> Renta variable | E159: =IFERROR(IF(JHers!E13="","",JHers!E13),"") -> US small/mid-cap growth | F159: =IFERROR(IF(JHers!F13="","",JHers!F13),"") -> Estados Unidos | G159: =IFERROR(IF(JHers!G13="","",JHers!G13),"") -> Small & mid cap growth / tecnología / industriales | H159: =IFERROR(IF(JHers!H13="","",JHers!H13),"") -> US Venture Fund | ... K159: =IFERROR(IF(JHers!K13="","",JHers!K13),"") -> NO_DATO
A160: =IFERROR(IF(JHers!A14="","",JHers!A14),"") -> Aaron Schaechterle | B160: =IFERROR(IF(JHers!B14="","",JHers!B14),"") -> Portfolio Manager | Research Analyst | C160: =IFERROR(IF(JHers!C14="","",JHers!C14),"") -> Portfolio Manager + Analista | D160: =IFERROR(IF(JHers!D14="","",JHers!D14),"") -> Renta variable | E160: =IFERROR(IF(JHers!E14="","",JHers!E14),"") -> US SMID Cap Growth | F160: =IFERROR(IF(JHers!F14="","",JHers!F14),"") -> Estados Unidos | G160: =IFERROR(IF(JHers!G14="","",JHers!G14),"") -> Small & mid cap growth / modelos de negocio diferenciados | H160: =IFERROR(IF(JHers!H14="","",JHers!H14),"") -> US SMID Cap Growth Managed Account | ... K160: =IFERROR(IF(JHers!K14="","",JHers!K14),"") -> https://www.janushenderson.com/en-us/advisor/product/us-smid-cap-growth-managed-account/
... A254: =IFERROR(IF(JHers!A108="","",JHers!A108),"") -> Nicolas Scherf | B254: =IFERROR(IF(JHers!B108="","",JHers!B108),"") -> Portfolio Manager | C254: =IFERROR(IF(JHers!C108="","",JHers!C108),"") -> Portfolio Manager | D254: =IFERROR(IF(JHers!D108="","",JHers!D108),"") -> Renta variable | E254: =IFERROR(IF(JHers!E108="","",JHers!E108),"") -> Global property equities | F254: =IFERROR(IF(JHers!F108="","",JHers!F108),"") -> Global | G254: =IFERROR(IF(JHers!G108="","",JHers!G108),"") -> Inmobiliario cotizado global | H254: =IFERROR(IF(JHers!H108="","",JHers!H108),"") -> Global Property Equities strategies | ... K254: =IFERROR(IF(JHers!K108="","",JHers!K108),"") -> NO_DATO
A255: =IFERROR(IF(JHers!#REF!="","",JHers!#REF!),"") | B255: =IFERROR(IF(JHers!#REF!="","",JHers!#REF!),"") | C255: =IFERROR(IF(JHers!#REF!="","",JHers!#REF!),"") | D255: =IFERROR(IF(JHers!#REF!="","",JHers!#REF!),"") | E255: =IFERROR(IF(JHers!#REF!="","",JHers!#REF!),"") | F255: =IFERROR(IF(JHers!#REF!="","",JHers!#REF!),"") | G255: =IFERROR(IF(JHers!#REF!="","",JHers!#REF!),"") | H255: =IFERROR(IF(JHers!#REF!="","",JHers!#REF!),"") | ... K255: =IFERROR(IF(JHers!#REF!="","",JHers!#REF!),"")
A256: =IFERROR(IF(JHers!A109="","",JHers!A109),"") -> Oliver Bardot, CFA | B256: =IFERROR(IF(JHers!B109="","",JHers!B109),"") -> Portfolio Manager | C256: =IFERROR(IF(JHers!C109="","",JHers!C109),"") -> Portfolio Manager | D256: =IFERROR(IF(JHers!D109="","",JHers!D109),"") -> Renta fija | E256: =IFERROR(IF(JHers!E109="","",JHers!E109),"") -> Global bonds / strategic bond | F256: =IFERROR(IF(JHers!F109="","",JHers!F109),"") -> Global | G256: =IFERROR(IF(JHers!G109="","",JHers!G109),"") -> Bonos globales / crédito IG y HY | H256: =IFERROR(IF(JHers!H109="","",JHers!H109),"") -> Strategic Bond & Global Bond strategies | ... K256: =IFERROR(IF(JHers!K109="","",JHers!K109),"") -> NO_DATO
A257: =IFERROR(IF(JHers!A110="","",JHers!A110),"") -> Ollie Beckett | B257: =IFERROR(IF(JHers!B110="","",JHers!B110),"") -> Portfolio Manager | C257: =IFERROR(IF(JHers!C110="","",JHers!C110),"") -> Portfolio Manager | D257: =IFERROR(IF(JHers!D110="","",JHers!D110),"") -> Renta variable | E257: =IFERROR(IF(JHers!E110="","",JHers!E110),"") -> European equities / small & mid cap | F257: =IFERROR(IF(JHers!F110="","",JHers!F110),"") -> Europa | G257: =IFERROR(IF(JHers!G110="","",JHers!G110),"") -> Renta variable europea / small caps | H257: =IFERROR(IF(JHers!H110="","",JHers!H110),"") -> European Equities strategies | ... K257: =IFERROR(IF(JHers!K110="","",JHers!K110),"") -> NO_DATO
A258: =IFERROR(IF(JHers!A111="","",JHers!A111),"") -> Priyank Shah | B258: =IFERROR(IF(JHers!B111="","",JHers!B111),"") -> Portfolio Manager | C258: =IFERROR(IF(JHers!C111="","",JHers!C111),"") -> Portfolio Manager | D258: =IFERROR(IF(JHers!D111="","",JHers!D111),"") -> Renta fija | E258: =IFERROR(IF(JHers!E111="","",JHers!E111),"") -> Global short duration & liquidity | F258: =IFERROR(IF(JHers!F111="","",JHers!F111),"") -> Global | G258: =IFERROR(IF(JHers!G111="","",JHers!G111),"") -> Renta fija corto plazo / gestión de tipos y divisas | H258: =IFERROR(IF(JHers!H111="","",JHers!H111),"") -> Global Short Duration & Liquidity strategies | ... K258: =IFERROR(IF(JHers!K111="","",JHers!K111),"") -> NO_DATO
A259: =IFERROR(IF(JHers!A112="","",JHers!A112),"") -> Richard Clode, CFA | B259: =IFERROR(IF(JHers!B112="","",JHers!B112),"") -> Portfolio Manager | C259: =IFERROR(IF(JHers!C112="","",JHers!C112),"") -> Portfolio Manager | D259: =IFERROR(IF(JHers!D112="","",JHers!D112),"") -> Renta variable | E259: =IFERROR(IF(JHers!E112="","",JHers!E112),"") -> Global technology equities | F259: =IFERROR(IF(JHers!F112="","",JHers!F112),"") -> Global | G259: =IFERROR(IF(JHers!G112="","",JHers!G112),"") -> Tecnología | H259: =IFERROR(IF(JHers!H112="","",JHers!H112),"") -> Global Technology Leaders strategies | ... K259: =IFERROR(IF(JHers!K112="","",JHers!K112),"") -> NO_DATO
A260: =IFERROR(IF(JHers!A113="","",JHers!A113),"") -> Robert Roszkowski | B260: =IFERROR(IF(JHers!B113="","",JHers!B113),"") -> Portfolio Manager | C260: =IFERROR(IF(JHers!C113="","",JHers!C113),"") -> Portfolio Manager | D260: =IFERROR(IF(JHers!D113="","",JHers!D113),"") -> Renta fija | E260: =IFERROR(IF(JHers!E113="","",JHers!E113),"") -> Global short duration & liquidity | F260: =IFERROR(IF(JHers!F113="","",JHers!F113),"") -> Global | G260: =IFERROR(IF(JHers!G113="","",JHers!G113),"") -> Renta fija corto plazo / modelos cuantitativos | H260: =IFERROR(IF(JHers!H113="","",JHers!H113),"") -> Global Short Duration & Liquidity strategies | ... K260: =IFERROR(IF(JHers!K113="","",JHers!K113),"") -> NO_DATO
...

Sheet JHers
A1: Column1 | B1: Column2 | C1: Column3 | D1: Column4 | E1: Column5 | F1: Column6 | G1: Column7 | H1: Column8 | I1: Column9 | J1: Column10 | K1: Column11
A2: Nombre_completo_profesional | B2: Rol_oficial | C2: Tipo_rol | D2: Clase_activo_principal | E2: Sub_clase_activo_o_estilo | F2: Region_principal | G2: Tematica_principal | H2: Nombre_fondo | I2: ISIN_o_ticker_principal | J2: URL_bio_profesional | K2: URL_fondo
A3: Allan Maymin | B3: Co-Head of Global Asset Allocation | Portfolio Manager | C3: Portfolio Manager | D3: Multiactivo | E3: Global adaptive multi-asset allocation | F3: Global | G3: Asignación de activos / multiactivo cuantitativo | H3: Global Adaptive Multi-Asset Fund | I3: IE000757TN66 | J3: https://www.janushenderson.com/corporate/bio/allan-maymin/ | K3: https://www.janushenderson.com/es-es/advisor/product/janus-henderson-global-adaptive-multi-asset-fund/
A4: Daniel Sullivan | B4: Portfolio Manager (Head of Global Natural Resources) | C4: Portfolio Manager | D4: Renta variable | E4: Global natural resources equities | F4: Global | G4: Recursos naturales / energía / transición energética | H4: Global Natural Resources Fund | I4: ETL0331AU | J4: https://www.janushenderson.com/corporate/bio/daniel-sullivan/ | K4: https://www.janushenderson.com/en-au/adviser/product/janus-henderson-global-natural-resources-fund/
A5: Darko Kuzmanovic | B5: Portfolio Manager (Global Natural Resources Team) | C5: Portfolio Manager | D5: Renta variable | E5: Global natural resources equities | F5: Global | G5: Recursos naturales / minería / energía | H5: Global Natural Resources Fund | I5: ETL0331AU | J5: https://www.janushenderson.com/en-au/investor/bio/darko-kuzmanovic/ | K5: https://www.janushenderson.com/en-au/adviser/product/janus-henderson-global-natural-resources-fund/
A6: Dillan Shah, CFA | B6: Quantitative Research Analyst | C6: Analista | D6: Renta fija | E6: Renta fija global cuantitativa | F6: Global | G6: Bonos globales / renta fija cuantitativa | H6: NO_DATO | I6: NO_DATO | J6: https://www.janushenderson.com/en-us/advisor/bio/dillan-shah/ | K6: NO_DATO
A7: James Briggs, CFA | B7: Portfolio Manager (Corporate Credit Team) | C7: Portfolio Manager | D7: Renta fija | E7: Crédito corporativo investment grade / Buy & Maintain | F7: Global | G7: Crédito corporativo IG / carteras buy & maintain / ESG en renta fija | H7: Global Investment Grade & Buy and Maintain Credit Strategies | I7: NO_DATO | J7: https://www.janushenderson.com/en-gb/investor/bio/james-briggs-aca-cfa/ | K7: NO_DATO
A8: Mark Richardson | B8: Portfolio Manager (Diversified Alternatives Team) | C8: Portfolio Manager | D8: Alternativos | E8: Diversified alternatives / estrategias cuantitativas | F8: Global | G8: Alternativos líquidos / estrategias sistemáticas | H8: Diversified Alternatives quantitative strategies | I8: NO_DATO | J8: https://www.janushenderson.com/en-be/advisor/bio/mark-richardson-dphil/ | K8: NO_DATO
A9: Nick Schommer, CFA | B9: Portfolio Manager | C9: Portfolio Manager | D9: Renta variable | E9: US large/mid-cap growth | F9: Estados Unidos | G9: Renta variable estadounidense growth | H9: US Growth / related US equity growth strategies | I9: NO_DATO | J9: https://www.janushenderson.com/en-us/advisor/bio/nick-schommer-cfa/ | K9: NO_DATO
A10: Nick Schommer, CFA | B10: Portfolio Manager | C10: Portfolio Manager | D10: Renta variable | E10: US mid-cap blend / contrarian | F10: Estados Unidos | G10: Renta variable estadounidense / enfoque contrarian | H10: Janus Henderson Contrarian Fund | I10: NO_DATO | J10: https://www.janushenderson.com/en-us/advisor/bio/nick-schommer-cfa/ | K10: NO_DATO
A11: Oliver Blackbourn, CFA | B11: Portfolio Manager (Multi-Asset Team) | C11: Portfolio Manager | D11: Multiactivo | E11: Flexible multi-asset portfolios | F11: Global | G11: Multiactivo global / visión macro | H11: Multi-Asset flexible strategies | I11: NO_DATO | J11: https://www.janushenderson.com/en-gb/investor/bio/oliver-blackbourn-cfa/ | K11: NO_DATO
A12: Ali Dibadj | B12: Chief Executive Officer | C12: Otro | D12: Perfil ejecutivo | E12: Dirección corporativa / estrategia | F12: Global | G12: Gestión de activos / estrategia corporativa / ESG corporativo | H12: NO_DATO | I12: NO_DATO | J12: https://www.janushenderson.com/en-fi/advisor/bio/ali-dibadj/ | K12: NO_DATO
... A132: William Cassidy | B132: Chief Technology Officer | C132: Otro | D132: Perfil ejecutivo | E132: Tecnología e infraestructura corporativa | F132: Global | G132: Estrategia tecnológica / innovación / datos | H132: NO_DATO | I132: NO_DATO | J132: https://www.janushenderson.com/en/row/bio/william-cassidy/ | K132: NO_DATO

Sheet JH_Lote7
A1: Column1 | B1: Column2 | C1: Column3 | D1: Column4 | E1: Column5 | F1: Column6 | G1: Column7 | H1: Column8 | I1: Column9 | J1: Column10 | K1: Column11
A2: Nombre_completo_profesional | B2: Rol_oficial | C2: Tipo_rol | D2: Clase_activo_principal | E2: Sub_clase_activo_o_estilo | F2: Region_principal | G2: Tematica_principal | H2: Nombre_fondo | I2: ISIN_o_ticker_principal | J2: URL_bio_profesional | K2: URL_fondo
A3: Oliver Bardot, CFA | B3: Portfolio Manager | C3: Gestor | D3: Renta fija | E3: Global bonds / strategic bond | F3: Global | G3: Bonos globales / crédito IG y HY | H3: Strategic Bond & Global Bond strategies | I3: NO_DATO | J3: https://www.janushenderson.com/corporate/bio/oliver-bardot-cfa/ | K3: NO_DATO
A4: Ollie Beckett | B4: Portfolio Manager | C4: Gestor | D4: Renta variable | E4: European equities / small & mid cap | F4: Europa | G4: Renta variable europea / small caps | H4: European Equities strategies | I4: NO_DATO | J4: https://www.janushenderson.com/corporate/bio/ollie-beckett/ | K4: NO_DATO
A5: Priyank Shah | B5: Portfolio Manager | C5: Gestor | D5: Renta fija | E5: Global short duration & liquidity | F5: Global | G5: Renta fija corto plazo / gestión de tipos y divisas | H5: Global Short Duration & Liquidity strategies | I5: NO_DATO | J5: https://www.janushenderson.com/en-gb/investor/bio/priyank-shah/ | K5: NO_DATO
A6: Richard Clode, CFA | B6: Portfolio Manager | C6: Gestor | D6: Renta variable | E6: Global technology equities | F6: Global | G6: Tecnología | H6: Global Technology Leaders strategies | I6: NO_DATO | J6: https://www.janushenderson.com/en-gb/investor/bio/richard-clode/ | K6: NO_DATO
A7: Robert Roszkowski | B7: Portfolio Manager | C7: Gestor | D7: Renta fija | E7: Global short duration & liquidity | F7: Global | G7: Renta fija corto plazo / modelos cuantitativos | H7: Global Short Duration & Liquidity strategies | I7: NO_DATO | J7: https://www.janushenderson.com/en-us/institutional/bio/robert-roszkowski/ | K7: NO_DATO
A8: Robert Schramm-Fuchs | B8: Portfolio Manager | C8: Gestor | D8: Renta variable | E8: European large-cap equities | F8: Europa | G8: Renta variable europea / large cap | H8: European Large Cap Equities strategies | I8: NO_DATO | J8: https://www.janushenderson.com/en-gb/investor/bio/robert-schramm-fuchs/ | K8: NO_DATO
A9: Rory Stokes, CFA | B9: Portfolio Manager | C9: Gestor | D9: Renta variable | E9: European equities | F9: Europa | G9: Renta variable europea | H9: European Equities strategies | I9: NO_DATO | J9: https://www.janushenderson.com/latam-other/advisor/bio/rory-stokes-cfa/ | K9: NO_DATO
A10: Sat Duhra | B10: Portfolio Manager | C10: Gestor | D10: Renta variable | E10: Asia ex Japan equities | F10: Asia Pacífico (ex Japón) | G10: Renta variable asiática | H10: Asia ex Japan Equity strategies | I10: NO_DATO | J10: https://www.janushenderson.com/en-gb/adviser/bio/sat-duhra/ | K10: NO_DATO
A11: Scott Stutzman, CFA | B11: Portfolio Manager | Research Analyst | C11: Gestor+Analista | D11: Renta variable | E11: US small/mid-cap growth equities | F11: Estados Unidos | G11: Small & mid cap growth / industriales y materiales | H11: US Small/Mid-Cap Growth strategies | I11: NO_DATO | J11: https://www.janushenderson.com/en-us/advisor/bio/scott-stutzman-cfa/ | K11: NO_DATO
A12: Seth Meyer, CFA | B12: Global Head of Client Portfolio Management | Portfolio Manager | C12: Gestor | D12: Renta variable / Renta fija | E12: Client portfolio management (equity & FI) | F12: Global | G12: Comunicación con clientes / estrategia comercial multi-clase de activo | H12: NO_DATO | I12: NO_DATO | J12: https://www.janushenderson.com/en-us/advisor/bio/seth-meyer-cfa/ | K12: NO_DATO
... A26: William Cassidy | B26: Chief Technology Officer | C26: Otro | D26: NO_DATO | E26: Tecnología e infraestructura corporativa | F26: Global | G26: Estrategia tecnológica / innovación / datos | H26: NO_DATO | I26: NO_DATO | J26: https://www.janushenderson.com/en/row/bio/william-cassidy/ | K26: NO_DATO

Sheet JH_Lote6
A1: Column1 | B1: Column2 | C1: Column3 | D1: Column4 | E1: Column5 | F1: Column6 | G1: Column7 | H1: Column8 | I1: Column9 | J1: Column10 | K1: Column11
A2: Nombre_completo_profesional | B2: Rol_oficial | C2: Tipo_rol | D2: Clase_activo_principal | E2: Sub_clase_activo_o_estilo | F2: Region_principal | G2: Tematica_principal | H2: Nombre_fondo | I2: ISIN_o_ticker_principal | J2: URL_bio_profesional | K2: URL_fondo
A3: Jenna Barnard, CFA | B3: Head of Global Bonds | Portfolio Manager | C3: Gestor | D3: Renta fija | E3: Global bonds / strategic bond | F3: Global | G3: Bonos globales / renta fija flexible | H3: Strategic Bond y Global Bond strategies | I3: NO_DATO | J3: https://www.janushenderson.com/en-gb/investor/bio/jenna-barnard-cfa/ | K3: NO_DATO
A4: Jeremiah Buckley, CFA | B4: Portfolio Manager | C4: Gestor | D4: Renta variable | E4: US multi-sector large-cap equities | F4: Estados Unidos | G4: Renta variable estadounidense multitemática / balanced | H4: US Growth & Balanced strategies | I4: NO_DATO | J4: https://www.janushenderson.com/en-us/advisor/bio/jeremiah-buckley/ | K4: NO_DATO
A5: Jeremy Tjaden, CFA | B5: Portfolio Manager | Analyst | Quantitative Solutions | C5: Gestor | D5: Renta variable | E5: Quantitative equity solutions | F5: Global | G5: Renta variable cuantitativa / indexada | H5: Quantitative Solutions strategies | I5: NO_DATO | J5: https://www.janushenderson.com/en-pt/advisor/bio/jeremy-tjaden-cfa/ | K5: NO_DATO
A6: Job Curtis, ASIP | B6: Portfolio Manager | C6: Gestor | D6: Renta variable | E6: UK & global equity income | F6: Reino Unido / Global | G6: Renta variable de dividendo / income | H6: City of London Investment Trust & Global Equity Income strategies | I6: NO_DATO | J6: https://www.marketscreener.com/insider/JOB-CURTIS-A03P0E/ | K6: NO_DATO
A7: John Griffiths | B7: Portfolio Manager | C7: Gestor | D7: Alternativos | E7: Diversified alternatives / absolute return | F7: Global | G7: Alternativos líquidos / retorno absoluto | H7: Diversified Alternatives strategies | I7: NO_DATO | J7: https://www.janushenderson.com/corporate/bio/john-griffiths/ | K7: NO_DATO
A8: John Jordan | B8: Portfolio Manager | Research Analyst | C8: Gestor+Analista | D8: Renta variable | E8: Global financials equities | F8: Global | G8: Sector financiero global | H8: Global Financials strategies | I8: NO_DATO | J8: https://www.janushenderson.com/en-gb/adviser/bio/john-jordan/ | K8: NO_DATO
A9: John Kerschner, CFA | B9: Global Head of Securitised Products | Portfolio Manager | C9: Gestor | D9: Renta fija | E9: Securitised products / structured credit | F9: Global | G9: Crédito titulizado / MBS / ABS | H9: Securitised Credit & Core Plus strategies | I9: NO_DATO | J9: https://www.janushenderson.com/en-gb/investor/bio/john-kerschner/ | K9: NO_DATO
A10: John King | B10: Associate Portfolio Manager | C10: Gestor | D10: Alternativos | E10: Diversified alternatives | F10: Global | G10: Alternativos líquidos / multiestrategia | H10: Diversified Alternatives strategies | I10: NO_DATO | J10: https://www.janushenderson.com/en-us/investor/bio/john-king/ | K10: NO_DATO
A11: John Lloyd | B11: Global Head of Multi-Sector Credit | Portfolio Manager | C11: Gestor | D11: Renta fija | E11: Multi-sector credit | F11: Global | G11: Crédito multisectorial / investment grade y high yield | H11: Multi-Sector Credit strategies | I11: NO_DATO | J11: https://www.janushenderson.com/en-gb/adviser/bio/john-lloyd/ | K11: NO_DATO
A12: Jonathan Cofsky, CFA | B12: Portfolio Manager | Research Analyst | Technology Co-Sector Lead | C12: Gestor+Analista | D12: Renta variable | E12: Global technology & innovation equities | F12: Global | G12: Tecnología | H12: Global Technology & Innovation strategies | I12: NO_DATO | J12: https://www.janushenderson.com/en-us/advisor/bio/jonathan-cofsky-cfa/ | K12: NO_DATO
... A36: Nicolas Scherf | B36: Portfolio Manager | C36: Gestor | D36: Renta variable | E36: Global property equities | F36: Global | G36: Inmobiliario cotizado global | H36: Global Property Equities strategies | I36: NO_DATO | J36: https://www.janushenderson.com/en-us/advisor/bio/nicolas-scherf/ | K36: NO_DATO

Sheet JH_Lote5
A1: Column1 | B1: Column2 | C1: Column3 | D1: Column4 | E1: Column5 | F1: Column6 | G1: Column7 | H1: Column8 | I1: Column9 | J1: Column10 | K1: Column11
A2: Nombre_completo_profesional | B2: Rol_oficial | C2: Tipo_rol | D2: Clase_activo_principal | E2: Sub_clase_activo_o_estilo | F2: Region_principal | G2: Tematica_principal | H2: Nombre_fondo | I2: ISIN_o_ticker_principal | J2: URL_bio_profesional | K2: URL_fondo
A3: David Smith, CFA | B3: Portfolio Manager | C3: Gestor | D3: Renta variable | E3: UK & global equity income | F3: Reino Unido / Global | G3: Renta variable de dividendo / income | H3: Janus Henderson UK Responsible Income Fund | I3: GB0005030373 | J3: https://www.janushenderson.com/en-gb/investor/bio/david-smith/ | K3: NO_DATO
A4: Denis Struc | B4: Portfolio Manager | C4: Gestor | D4: Renta fija | E4: Secured credit / securitised debt | F4: Global | G4: Crédito titulizado / ABS | H4: Secured Credit strategies | I4: NO_DATO | J4: https://www.janushenderson.com/corporate/bio/denis-struc/ | K4: NO_DATO
A5: Denny Fish | B5: Portfolio Manager | Research Analyst | C5: Gestor+Analista | D5: Renta variable | E5: Global technology & innovation equities | F5: Global | G5: Tecnología | H5: Global Technology & Innovation strategies | I5: NO_DATO | J5: https://www.janushenderson.com/en-us/advisor/bio/denny-fish/ | K5: NO_DATO
A6: Dimitri Diamand | B6: Associate Portfolio Manager | C6: Gestor | D6: Renta fija | E6: Australian fixed interest | F6: Australia | G6: Renta fija australiana / duración | H6: Australian Fixed Interest strategies | I6: NO_DATO | J6: https://www.janushenderson.com/en-hk/investor/bio/dimitri-diamand/ | K6: NO_DATO
A7: Douglas Turnbull, CFA | B7: Portfolio Manager | Research Analyst | C7: Gestor+Analista | D7: Renta variable | E7: Emerging markets equities | F7: Mercados emergentes | G7: Renta variable emergente / tecnología | H7: Emerging Market Equity strategies | I7: NO_DATO | J7: https://www.janushenderson.com/en-ch/investor/bio/douglas-turnbull/ | K7: NO_DATO
A8: Dylan Bourke, CFA | B8: Portfolio Manager | C8: Gestor | D8: Renta fija | E8: Global short duration income | F8: Global | G8: Renta fija a corto plazo / liquidez | H8: Global Short Duration & Liquidity strategies | I8: NO_DATO | J8: https://www.janushenderson.com/en-se/advisor/bio/dylan-bourke/ | K8: NO_DATO
A9: Eduardo Jimenez Martin, CFA, FRM | B9: Portfolio Manager | C9: Gestor | D9: Multiactivo | E9: Global multi-asset | F9: Global | G9: Multiactivo / asignación cuantitativa | H9: Multi-Asset strategies | I9: NO_DATO | J9: https://www.janushenderson.com/corporate/bio/eduardo-jimenez-martin-cfa-frm/ | K9: NO_DATO
A10: Edward Parcell | B10: Portfolio Manager | C10: Gestor | D10: Alternativos | E10: Diversified alternatives / multi-strategy | F10: Global | G10: Alternativos líquidos / sistemáticos | H10: Diversified Alternatives strategies | I10: NO_DATO | J10: https://www.janushenderson.com/en-gb/investor/bio/edward-parcell/ | K10: NO_DATO
A11: Edward Su, CFA | B11: Portfolio Manager | Research Analyst | C11: Gestor+Analista | D11: Renta variable | E11: Consumer equities | F11: Global | G11: Consumo global / growth | H11: Consumer Sector strategies | I11: NO_DATO | J11: https://www.janushenderson.com/en-us/advisor/bio/edward-su-cfa/ | K11: NO_DATO
A12: Faizan Baig, CFA | B12: Portfolio Manager | C12: Gestor | D12: Renta variable | E12: Global equity income | F12: Global | G12: Renta variable global de dividendo / income | H12: Global Equity Income strategies | I12: NO_DATO | J12: https://www.janushenderson.com/en-hk/investor/bio/faizan-baig-cfa/ | K12: NO_DATO
... A28: Jay Sivapalan, CFA | B28: Head of Australian Fixed Interest | Portfolio Manager | C28: Gestor | D28: Renta fija | E28: Australian fixed interest | F28: Australia | G28: Renta fija australiana / tipos y crédito | H28: Australian Fixed Interest strategies | I28: NO_DATO | J28: https://www.janushenderson.com/en-au/investor/bio/jay-sivapalan-cfa/ | K28: NO_DATO

Sheet JH_lote4
A1: Column1 | B1: Column2 | C1: Column3 | D1: Column4 | E1: Column5 | F1: Column6 | G1: Column7 | H1: Column8 | I1: Column9 | J1: Column10 | K1: Column11
A2: Nombre_completo_profesional | B2: Rol_oficial | C2: Tipo_rol | D2: Clase_activo_principal | E2: Sub_clase_activo_o_estilo | F2: Region_principal | G2: Tematica_principal | H2: Nombre_fondo | I2: ISIN_o_ticker_principal | J2: URL_bio_profesional | K2: URL_fondo
A3: Carlo Castronovo | B3: Portfolio Manager | C3: Gestor | D3: Alternativos | E3: Diversified alternatives / multi-strategy | F3: Global | G3: Alternativos líquidos / estrategias multiestrategia | H3: Global Multi-Strategy funds | I3: NO_DATO | J3: https://www.janushenderson.com/middle-east/institutional/bio/carlo-castronovo/ | K3: NO_DATO
A4: Charlotte Greville, CFA | B4: Portfolio Manager | C4: Gestor | D4: Renta variable | E4: Global equity income | F4: Global | G4: Renta variable global de dividendo / income | H4: Global Equity Income strategies | I4: NO_DATO | J4: https://www.janushenderson.com/en-us/advisor/bio/charlotte-greville-cfa/ | K4: NO_DATO
A5: Christopher O'Malley, CFA | B5: Portfolio Manager | Research Analyst | C5: Gestor+Analista | D5: Renta variable | E5: Global alpha equities | F5: Global | G5: Renta variable global / enfoque growth de alta convicción | H5: Global Alpha Equity strategies | I5: NO_DATO | J5: https://www.janushenderson.com/en-us/offshore/bio/christopher-omalley-cfa/ | K5: NO_DATO
A6: Cody Wheaton, CFA | B6: Portfolio Manager | Research Analyst | C6: Gestor+Analista | D6: Renta variable | E6: US mid-cap growth | F6: Estados Unidos | G6: Small & mid cap growth / financieros y consumo | H6: US Mid Cap Growth strategies | I6: NO_DATO | J6: https://www.janushenderson.com/en-us/advisor/bio/philip-cody-wheaton-cfa/ | K6: NO_DATO
A7: Craig Kempler, CFA | B7: Portfolio Manager | C7: Gestor | D7: Renta variable | E7: US SMID value | F7: Estados Unidos | G7: Renta variable value en small & mid caps | H7: US SMID Value strategies | I7: NO_DATO | J7: https://www.janushenderson.com/en-dk/investor/bio/craig-kempler-cfa/ | K7: NO_DATO
A8: Daniel Lyons, PhD, CFA | B8: Portfolio Manager | Research Analyst | C8: Gestor+Analista | D8: Renta variable | E8: Global healthcare / biotech | F8: Global | G8: Biotecnología y life science tools | H8: Health Care & Biotech strategies | I8: NO_DATO | J8: https://www.janushenderson.com/en-be/advisor/bio/daniel-lyons-phd-cfa/ | K8: NO_DATO
A9: Daniel Siluk | B9: Head of Global Short Duration & Liquidity | Portfolio Manager | C9: Gestor | D9: Renta fija | E9: Short duration & liquidity | F9: Global | G9: Renta fija a corto plazo / liquidez | H9: Global Short Duration & Liquidity strategies | I9: NO_DATO | J9: https://www.janushendersoncharitable.org/bio/daniel-siluk/ | K9: NO_DATO
A10: Danny Greenberger | B10: Portfolio Manager | C10: Gestor | D10: Renta variable | E10: Global property equities | F10: Global | G10: Inmobiliario cotizado / real estate long/short | H10: Global Property Equities strategies | I10: NO_DATO | J10: https://www.janushenderson.com/en-us/advisor/bio/daniel-greenberger/ | K10: NO_DATO
A11: David Elms | B11: Head of Diversified Alternatives | Portfolio Manager | C11: Gestor | D11: Alternativos | E11: Diversified alternatives / absolute return | F11: Global | G11: Alternativos líquidos / retorno absoluto | H11: Diversified Alternatives strategies | I11: NO_DATO | J11: https://www.janushenderson.com/en-us/advisor/bio/david-elms/ | K11: NO_DATO
A12: David Padulo, CFA | B12: Portfolio Manager | C12: Gestor | D12: Renta fija | E12: Investment grade corporate credit | F12: Global | G12: Crédito corporativo investment grade | H12: Corporate Credit strategies | I12: NO_DATO | J12: https://www.janushenderson.com/nl-nl/investor/bio/david-padulo-cfa/ | K12: NO_DATO

Sheet JH_lote3
A1: Column1 | B1: Column2 | C1: Column3 | D1: Column4 | E1: Column5 | F1: Column6 | G1: Column7 | H1: Column8 | I1: Column9 | J1: Column10 | K1: Column11
A2: Nombre_completo_profesional | B2: Rol_oficial | C2: Tipo_rol | D2: Clase_activo_principal | E2: Sub_clase_activo_o_estilo | F2: Region_principal | G2: Tematica_principal | H2: Nombre_fondo | I2: ISIN_o_ticker_principal | J2: URL_bio_profesional | K2: URL_fondo
A3: Arjun Bhandari, CFA | B3: Portfolio Manager | C3: Gestor | D3: Renta fija | E3: Global bonds | F3: Global | G3: Bonos globales / renta fija agregada | H3: Global Bonds strategies | I3: NO_DATO | J3: https://www.janushenderson.com/en-us/advisor/bio/arjun-bhandari-cfa/ | K3: NO_DATO
A4: Ben Jones | B4: Portfolio Manager | C4: Gestor | D4: Alternativos | E4: Diversified alternatives | F4: Global | G4: Alternativos líquidos / multiestrategia | H4: Diversified Alternatives strategies | I4: NO_DATO | J4: https://www.janushenderson.com/en-gb/investor/bio/ben-jones/ | K4: NO_DATO
A5: Ben Lofthouse, CFA | B5: Head of Global Equity Income | Portfolio Manager | C5: Gestor | D5: Renta variable | E5: Global equity income | F5: Global | G5: Renta variable global de dividendo / income | H5: Global Equity Income Fund | I5: NO_DATO | J5: https://www.janushenderson.com/en-gb/investor/bio/ben-lofthouse/ | K5: NO_DATO
A6: Ben Wallace | B6: Portfolio Manager | C6: Gestor | D6: Renta variable | E6: Absolute return equities | F6: Reino Unido / Europa | G6: Renta variable long/short / retorno absoluto | H6: Absolute Return Equities strategies | I6: NO_DATO | J6: https://www.janushenderson.com/corporate/bio/ben-wallace/ | K6: NO_DATO
A7: Benjamin Wang, CFA | B7: Portfolio Manager | Quantitative Solutions | C7: Gestor | D7: Renta variable | E7: Quantitative equity / index solutions | F7: Global | G7: Renta variable cuantitativa / indexada | H7: Quantitative Solutions strategies | I7: NO_DATO | J7: https://www.janushenderson.com/en-sg/investor/bio/benjamin-wang-cfa/ | K7: NO_DATO
A8: Bent Lystbaek | B8: Portfolio Manager | C8: Gestor | D8: Renta fija | E8: Emerging Markets Debt Hard Currency | F8: Mercados emergentes | G8: Deuda emergente en divisa fuerte | H8: Emerging Markets Debt Hard Currency strategies | I8: NO_DATO | J8: https://www.janushenderson.com/en-us/advisor/bio/bent-lystbaek/ | K8: NO_DATO
A9: Bradford Smith | B9: Portfolio Manager | C9: Gestor | D9: Renta fija | E9: Core Plus & corporate credit | F9: Global | G9: Crédito corporativo / renta fija Core Plus | H9: Core Plus and Corporate Credit strategies | I9: NO_DATO | J9: https://www.janushenderson.com/en-pt/advisor/bio/bradford-smith/ | K9: NO_DATO
A10: Brent Olson | B10: Portfolio Manager | C10: Gestor | D10: Renta fija | E10: Credit-focused strategies | F10: Global | G10: Crédito corporativo / enfoque fundamental | H10: Credit strategies | I10: NO_DATO | J10: https://www.janushenderson.com/en-gb/adviser/bio/brent-olson/ | K10: NO_DATO
A11: Brian Demain, CFA | B11: Portfolio Manager | C11: Gestor | D11: Renta variable | E11: US mid-cap growth | F11: Estados Unidos | G11: Renta variable estadounidense mid cap growth | H11: US Mid Cap Growth strategies | I11: NO_DATO | J11: https://www.janushenderson.com/en-ie/investor/bio/brian-demain-cfa/ | K11: NO_DATO
A12: Brian Recht | B12: Portfolio Manager | Research Analyst | C12: Gestor+Analista | D12: Renta variable | E12: US growth equities | F12: Estados Unidos | G12: Consumo y comunicaciones / growth | H12: US growth equity strategies | I12: NO_DATO | J12: https://www.janushenderson.com/en-gb/adviser/bio/brian-recht/ | K12: NO_DATO

Sheet JH_lote2
A1: Column1 | B1: Column2 | C1: Column3 | D1: Column4 | E1: Column5 | F1: Column6 | G1: Column7 | H1: Column8 | I1: Column9 | J1: Column10 | K1: Column11
A2: Nombre_completo_profesional | B2: Rol_oficial | C2: Tipo_rol | D2: Clase_activo_principal | E2: Sub_clase_activo_o_estilo | F2: Region_principal | G2: Tematica_principal | H2: Nombre_fondo | I2: ISIN_o_ticker_principal | J2: URL_bio_profesional | K2: URL_fondo
A3: Aaron Scully, CFA | B3: Portfolio Manager | C3: Gestor | D3: Renta variable | E3: Global sustainable equity | F3: Global | G3: ESG / sostenibilidad | H3: Horizon Global Sustainable Equity Fund | I3: NO_DATO | J3: https://www.janushenderson.com/en-us/advisor/bio/aaron-scully-cfa/ | K3: NO_DATO
A4: Aaron Scully, CFA | B4: Portfolio Manager | C4: Gestor | D4: Renta variable | E4: Global sustainable equity | F4: Global | G4: ESG / sostenibilidad | H4: Global Sustainable Equity strategies | I4: NO_DATO | J4: https://www.janushenderson.com/en-us/advisor/bio/aaron-scully-cfa/ | K4: NO_DATO
A5: Addison Maier | B5: Portfolio Manager | C5: Gestor | D5: Renta fija | E5: Global short duration income | F5: Global | G5: Renta fija corto plazo / liquidez | H5: Global Short Duration Income Fund | I5: IE00BZ771832 | J5: https://www.janushenderson.com/en-sg/investor/bio/addison-maier/ | K5: NO_DATO
A6: Addison Maier | B6: Portfolio Manager | C6: Gestor | D6: Renta fija | E6: Absolute return income | F6: Global | G6: Renta fija retorno absoluto | H6: Absolute Return Income Opportunities Fund | I6: NO_DATO | J6: https://www.janushenderson.com/en-sg/investor/bio/addison-maier/ | K6: NO_DATO
A7: Agustin Mohedas, PhD | B7: Portfolio Manager | Research Analyst | C7: Gestor+Analista | D7: Renta variable | E7: Global healthcare / biotechnology equities | F7: Global | G7: Biotecnología / salud | H7: Horizon Biotechnology Fund | I7: NO_DATO | J7: https://www.janushenderson.com/en-us/advisor/bio/agustin-mohedas-ph-d/ | K7: https://www.janushenderson.com/en-se/investor/product/janus-henderson-horizon-biotechnology-fund/
A8: Alex Crooke, ASIP | B8: Portfolio Manager | C8: Gestor | D8: Renta variable | E8: Global equity income | F8: Global | G8: Renta variable global de dividendo / income | H8: Global Equity Income strategies | I8: NO_DATO | J8: https://www.janushenderson.com/en-gb/adviser/bio/alex-crooke/ | K8: NO_DATO
A9: Alex Crooke, ASIP | B9: Portfolio Manager | C9: Gestor | D9: Renta variable | E9: Global dividend & income | F9: Global | G9: Renta variable global de dividendo / income | H9: Global Dividend & Income strategies | I9: NO_DATO | J9: https://www.janushenderson.com/en-gb/adviser/bio/alex-crooke/ | K9: NO_DATO
A10: Alex Veroude, CFA | B10: Head of Fixed Income | C10: Otro | D10: Renta fija | E10: Global fixed income leadership | F10: Global | G10: Gestión de renta fija / crédito / core | H10: NO_DATO | I10: NO_DATO | J10: https://www.janushenderson.com/en-gb/adviser/bio/alex-veroude-cfa/ | K10: NO_DATO
A11: Alexander Keen, CFA | B11: Portfolio Manager | C11: Gestor | D11: Alternativos | E11: Diversified alternatives | F11: Global | G11: Alternativos líquidos / multiestrategia | H11: Diversified Alternatives strategies | I11: NO_DATO | J11: https://www.janushenderson.com/en-gb/investor/bio/alexander-keen-cfa/ | K11: NO_DATO
A12: Alison Porter | B12: Portfolio Manager | C12: Gestor | D12: Renta variable | E12: Global technology equities | F12: Global | G12: Tecnología | H12: Global Technology Leaders strategies | I12: NO_DATO | J12: https://www.janushenderson.com/es-es/investor/bio/alison-porter/ | K12: NO_DATO
... A16: Andy Acker, CFA | B16: Portfolio Manager | C16: Gestor | D16: Renta variable | E16: Biotechnology equities | F16: Global | G16: Biotecnología | H16: Horizon Biotechnology Fund | I16: NO_DATO | J16: https://www.janushenderson.com/en-us/advisor/bio/andy-acker/ | K16: https://www.janushenderson.com/en-se/investor/product/janus-henderson-horizon-biotechnology-fund/

Sheet JH_Lote1
A1: Column1 | B1: Column2 | C1: Column3 | D1: Column4 | E1: Column5 | F1: Column6 | G1: Column7 | H1: Column8 | I1: Column9 | J1: Column10 | K1: Column11
A2: Nombre_completo_profesional | B2: Rol_oficial | C2: Tipo_rol | D2: Clase_activo_principal | E2: Sub_clase_activo_o_estilo | F2: Region_principal | G2: Tematica_principal | H2: Nombre_fondo | I2: ISIN_o_ticker_principal | J2: URL_bio_profesional | K2: URL_fondo
A3: Allan Maymin | B3: Co-Head of Global Asset Allocation | Portfolio Manager | C3: Gestor | D3: Multiactivo | E3: Global adaptive multi-asset allocation | F3: Global | G3: Asignación de activos / multiactivo cuantitativo | H3: Global Adaptive Multi-Asset Fund | I3: IE000757TN66 | J3: https://www.janushenderson.com/corporate/bio/allan-maymin/ | K3: https://www.janushenderson.com/es-es/advisor/product/janus-henderson-global-adaptive-multi-asset-fund/
A4: Daniel Sullivan | B4: Portfolio Manager (Head of Global Natural Resources) | C4: Gestor | D4: Renta variable | E4: Global natural resources equities | F4: Global | G4: Recursos naturales / energía / transición energética | H4: Global Natural Resources Fund | I4: ETL0331AU | J4: https://www.janushenderson.com/corporate/bio/daniel-sullivan/ | K4: https://www.janushenderson.com/en-au/adviser/product/janus-henderson-global-natural-resources-fund/
A5: Darko Kuzmanovic | B5: Portfolio Manager (Global Natural Resources Team) | C5: Gestor | D5: Renta variable | E5: Global natural resources equities | F5: Global | G5: Recursos naturales / minería / energía | H5: Global Natural Resources Fund | I5: ETL0331AU | J5: https://www.janushenderson.com/en-au/investor/bio/darko-kuzmanovic/ | K5: https://www.janushenderson.com/en-au/adviser/product/janus-henderson-global-natural-resources-fund/
A6: Dillan Shah, CFA | B6: Quantitative Research Analyst | C6: Analista | D6: Renta fija | E6: Renta fija global cuantitativa | F6: Global | G6: Bonos globales / renta fija cuantitativa | H6: NO_DATO | I6: NO_DATO | J6: https://www.janushenderson.com/en-us/advisor/bio/dillan-shah/ | K6: NO_DATO
A7: James Briggs, CFA | B7: Portfolio Manager (Corporate Credit Team) | C7: Gestor | D7: Renta fija | E7: Crédito corporativo investment grade / Buy & Maintain | F7: Global | G7: Crédito corporativo IG / carteras buy & maintain / ESG en renta fija | H7: Global Investment Grade & Buy and Maintain Credit Strategies | I7: NO_DATO | J7: https://www.janushenderson.com/en-gb/investor/bio/james-briggs-aca-cfa/ | K7: NO_DATO
A8: Mark Richardson | B8: Portfolio Manager (Diversified Alternatives Team) | C8: Gestor | D8: Alternativos | E8: Diversified alternatives / estrategias cuantitativas | F8: Global | G8: Alternativos líquidos / estrategias sistemáticas | H8: Diversified Alternatives quantitative strategies | I8: NO_DATO | J8: https://www.janushenderson.com/en-be/advisor/bio/mark-richardson-dphil/ | K8: NO_DATO
A9: Nick Schommer, CFA | B9: Portfolio Manager | C9: Gestor | D9: Renta variable | E9: US large/mid-cap growth | F9: Estados Unidos | G9: Renta variable estadounidense growth | H9: US Growth / related US equity growth strategies | I9: NO_DATO | J9: https://www.janushenderson.com/en-us/advisor/bio/nick-schommer-cfa/ | K9: NO_DATO
A10: Nick Schommer, CFA | B10: Portfolio Manager | C10: Gestor | D10: Renta variable | E10: US mid-cap blend / contrarian | F10: Estados Unidos | G10: Renta variable estadounidense / enfoque contrarian | H10: Janus Henderson Contrarian Fund | I10: NO_DATO | J10: https://www.janushenderson.com/en-us/advisor/bio/nick-schommer-cfa/ | K10: NO_DATO
A11: Oliver Blackbourn, CFA | B11: Portfolio Manager (Multi-Asset Team) | C11: Gestor | D11: Multiactivo | E11: Flexible multi-asset portfolios | F11: Global | G11: Multiactivo global / visión macro | H11: Multi-Asset flexible strategies | I11: NO_DATO | J11: https://www.janushenderson.com/en-gb/investor/bio/oliver-blackbourn-cfa/ | K11: NO_DATO
A12: Ali Dibadj | B12: Chief Executive Officer | C12: Otro | D12: NO_DATO | E12: Dirección corporativa / estrategia | F12: Global | G12: Gestión de activos / estrategia corporativa / ESG corporativo | H12: NO_DATO | I12: NO_DATO | J12: https://www.janushenderson.com/en-fi/advisor/bio/ali-dibadj/ | K12: NO_DATO
... A14: Aaron Schaechterle | B14: Portfolio Manager | Research Analyst | C14: Gestor+Analista | D14: Renta variable | E14: US SMID Cap Growth | F14: Estados Unidos | G14: Small & mid cap growth / modelos de negocio diferenciados | H14: US SMID Cap Growth Managed Account | I14: NO_DATO | J14: https://www.janushenderson.com/corporate/bio/aaron-schaechterle/ | K14: https://www.janushenderson.com/en-us/advisor/product/us-smid-cap-growth-managed-account/
